2020-12-30 11:01:42,281 ERROR: Exception on /user/jack [GET] [in /Users/mazzeogeorge/Code/Flask/tut/venv/lib/python3.7/site-packages/flask/app.py:1892]
Traceback (most recent call last):
  File "/Users/mazzeogeorge/Code/Flask/tut/venv/lib/python3.7/site-packages/flask/app.py", line 2447, in wsgi_app
    response = self.full_dispatch_request()
  File "/Users/mazzeogeorge/Code/Flask/tut/venv/lib/python3.7/site-packages/flask/app.py", line 1952, in full_dispatch_request
    rv = self.handle_user_exception(e)
  File "/Users/mazzeogeorge/Code/Flask/tut/venv/lib/python3.7/site-packages/flask/app.py", line 1821, in handle_user_exception
    reraise(exc_type, exc_value, tb)
  File "/Users/mazzeogeorge/Code/Flask/tut/venv/lib/python3.7/site-packages/flask/_compat.py", line 39, in reraise
    raise value
  File "/Users/mazzeogeorge/Code/Flask/tut/venv/lib/python3.7/site-packages/flask/app.py", line 1950, in full_dispatch_request
    rv = self.dispatch_request()
  File "/Users/mazzeogeorge/Code/Flask/tut/venv/lib/python3.7/site-packages/flask/app.py", line 1936, in dispatch_request
    return self.view_functions[rule.endpoint](**req.view_args)
  File "/Users/mazzeogeorge/Code/Flask/tut/venv/lib/python3.7/site-packages/flask_login/utils.py", line 272, in decorated_view
    return func(*args, **kwargs)
  File "/Users/mazzeogeorge/Code/Flask/tut/app/routes.py", line 91, in user
    return render_template('user.html', user=user, posts=posts, form=form)
  File "/Users/mazzeogeorge/Code/Flask/tut/venv/lib/python3.7/site-packages/flask/templating.py", line 140, in render_template
    ctx.app,
  File "/Users/mazzeogeorge/Code/Flask/tut/venv/lib/python3.7/site-packages/flask/templating.py", line 120, in _render
    rv = template.render(context)
  File "/Users/mazzeogeorge/Code/Flask/tut/venv/lib/python3.7/site-packages/jinja2/environment.py", line 1090, in render
    self.environment.handle_exception()
  File "/Users/mazzeogeorge/Code/Flask/tut/venv/lib/python3.7/site-packages/jinja2/environment.py", line 832, in handle_exception
    reraise(*rewrite_traceback_stack(source=source))
  File "/Users/mazzeogeorge/Code/Flask/tut/venv/lib/python3.7/site-packages/jinja2/_compat.py", line 28, in reraise
    raise value.with_traceback(tb)
  File "/Users/mazzeogeorge/Code/Flask/tut/app/templates/user.html", line 1, in top-level template code
    {% extends "base.html" %}
  File "/Users/mazzeogeorge/Code/Flask/tut/app/templates/base.html", line 30, in top-level template code
    {% block content %}{% endblock %}
  File "/Users/mazzeogeorge/Code/Flask/tut/app/templates/user.html", line 20, in block "content"
    {{ form.submit(value='Follow') }}
jinja2.exceptions.UndefinedError: 'app.forms.EmptyForm object' has no attribute 'submit'
2020-12-30 11:02:31,918 INFO: Microblog startup [in /Users/mazzeogeorge/Code/Flask/tut/app/__init__.py:46]
