2020-12-29 19:18:19,022 INFO: Microblog startup [in /Users/mazzeogeorge/Code/Flask/tut/app/__init__.py:46]
2020-12-29 19:18:29,054 ERROR: Exception on /edit_profile [POST] [in /Users/mazzeogeorge/Code/Flask/tut/venv/lib/python3.7/site-packages/flask/app.py:1892]
Traceback (most recent call last):
  File "/Users/mazzeogeorge/Code/Flask/tut/venv/lib/python3.7/site-packages/sqlalchemy/engine/base.py", line 1277, in _execute_context
    cursor, statement, parameters, context
  File "/Users/mazzeogeorge/Code/Flask/tut/venv/lib/python3.7/site-packages/sqlalchemy/engine/default.py", line 609, in do_execute
    cursor.execute(statement, parameters)
sqlite3.IntegrityError: UNIQUE constraint failed: user.username

The above exception was the direct cause of the following exception:

Traceback (most recent call last):
  File "/Users/mazzeogeorge/Code/Flask/tut/venv/lib/python3.7/site-packages/flask/app.py", line 2447, in wsgi_app
    response = self.full_dispatch_request()
  File "/Users/mazzeogeorge/Code/Flask/tut/venv/lib/python3.7/site-packages/flask/app.py", line 1952, in full_dispatch_request
    rv = self.handle_user_exception(e)
  File "/Users/mazzeogeorge/Code/Flask/tut/venv/lib/python3.7/site-packages/flask/app.py", line 1821, in handle_user_exception
    reraise(exc_type, exc_value, tb)
  File "/Users/mazzeogeorge/Code/Flask/tut/venv/lib/python3.7/site-packages/flask/_compat.py", line 39, in reraise
    raise value
  File "/Users/mazzeogeorge/Code/Flask/tut/venv/lib/python3.7/site-packages/flask/app.py", line 1950, in full_dispatch_request
    rv = self.dispatch_request()
  File "/Users/mazzeogeorge/Code/Flask/tut/venv/lib/python3.7/site-packages/flask/app.py", line 1936, in dispatch_request
    return self.view_functions[rule.endpoint](**req.view_args)
  File "/Users/mazzeogeorge/Code/Flask/tut/venv/lib/python3.7/site-packages/flask_login/utils.py", line 272, in decorated_view
    return func(*args, **kwargs)
  File "/Users/mazzeogeorge/Code/Flask/tut/app/routes.py", line 98, in edit_profile
    db.session.commit()
  File "/Users/mazzeogeorge/Code/Flask/tut/venv/lib/python3.7/site-packages/sqlalchemy/orm/scoping.py", line 163, in do
    return getattr(self.registry(), name)(*args, **kwargs)
  File "/Users/mazzeogeorge/Code/Flask/tut/venv/lib/python3.7/site-packages/sqlalchemy/orm/session.py", line 1046, in commit
    self.transaction.commit()
  File "/Users/mazzeogeorge/Code/Flask/tut/venv/lib/python3.7/site-packages/sqlalchemy/orm/session.py", line 504, in commit
    self._prepare_impl()
  File "/Users/mazzeogeorge/Code/Flask/tut/venv/lib/python3.7/site-packages/sqlalchemy/orm/session.py", line 483, in _prepare_impl
    self.session.flush()
  File "/Users/mazzeogeorge/Code/Flask/tut/venv/lib/python3.7/site-packages/sqlalchemy/orm/session.py", line 2540, in flush
    self._flush(objects)
  File "/Users/mazzeogeorge/Code/Flask/tut/venv/lib/python3.7/site-packages/sqlalchemy/orm/session.py", line 2682, in _flush
    transaction.rollback(_capture_exception=True)
  File "/Users/mazzeogeorge/Code/Flask/tut/venv/lib/python3.7/site-packages/sqlalchemy/util/langhelpers.py", line 70, in __exit__
    with_traceback=exc_tb,
  File "/Users/mazzeogeorge/Code/Flask/tut/venv/lib/python3.7/site-packages/sqlalchemy/util/compat.py", line 182, in raise_
    raise exception
  File "/Users/mazzeogeorge/Code/Flask/tut/venv/lib/python3.7/site-packages/sqlalchemy/orm/session.py", line 2642, in _flush
    flush_context.execute()
  File "/Users/mazzeogeorge/Code/Flask/tut/venv/lib/python3.7/site-packages/sqlalchemy/orm/unitofwork.py", line 422, in execute
    rec.execute(self)
  File "/Users/mazzeogeorge/Code/Flask/tut/venv/lib/python3.7/site-packages/sqlalchemy/orm/unitofwork.py", line 589, in execute
    uow,
  File "/Users/mazzeogeorge/Code/Flask/tut/venv/lib/python3.7/site-packages/sqlalchemy/orm/persistence.py", line 236, in save_obj
    update,
  File "/Users/mazzeogeorge/Code/Flask/tut/venv/lib/python3.7/site-packages/sqlalchemy/orm/persistence.py", line 995, in _emit_update_statements
    statement, multiparams
  File "/Users/mazzeogeorge/Code/Flask/tut/venv/lib/python3.7/site-packages/sqlalchemy/engine/base.py", line 1011, in execute
    return meth(self, multiparams, params)
  File "/Users/mazzeogeorge/Code/Flask/tut/venv/lib/python3.7/site-packages/sqlalchemy/sql/elements.py", line 298, in _execute_on_connection
    return connection._execute_clauseelement(self, multiparams, params)
  File "/Users/mazzeogeorge/Code/Flask/tut/venv/lib/python3.7/site-packages/sqlalchemy/engine/base.py", line 1130, in _execute_clauseelement
    distilled_params,
  File "/Users/mazzeogeorge/Code/Flask/tut/venv/lib/python3.7/site-packages/sqlalchemy/engine/base.py", line 1317, in _execute_context
    e, statement, parameters, cursor, context
  File "/Users/mazzeogeorge/Code/Flask/tut/venv/lib/python3.7/site-packages/sqlalchemy/engine/base.py", line 1511, in _handle_dbapi_exception
    sqlalchemy_exception, with_traceback=exc_info[2], from_=e
  File "/Users/mazzeogeorge/Code/Flask/tut/venv/lib/python3.7/site-packages/sqlalchemy/util/compat.py", line 182, in raise_
    raise exception
  File "/Users/mazzeogeorge/Code/Flask/tut/venv/lib/python3.7/site-packages/sqlalchemy/engine/base.py", line 1277, in _execute_context
    cursor, statement, parameters, context
  File "/Users/mazzeogeorge/Code/Flask/tut/venv/lib/python3.7/site-packages/sqlalchemy/engine/default.py", line 609, in do_execute
    cursor.execute(statement, parameters)
sqlalchemy.exc.IntegrityError: (sqlite3.IntegrityError) UNIQUE constraint failed: user.username
[SQL: UPDATE user SET username=?, about_me=? WHERE user.id = ?]
[parameters: ('jack', '', 6)]
(Background on this error at: http://sqlalche.me/e/13/gkpj)
2020-12-29 19:24:29,331 INFO: Microblog startup [in /Users/mazzeogeorge/Code/Flask/tut/app/__init__.py:46]
2020-12-29 20:04:40,764 INFO: Microblog startup [in /Users/mazzeogeorge/Code/Flask/tut/app/__init__.py:46]
2020-12-30 09:22:44,571 INFO: Microblog startup [in /Users/mazzeogeorge/Code/Flask/tut/app/__init__.py:46]
2020-12-30 09:23:04,242 INFO: Microblog startup [in /Users/mazzeogeorge/Code/Flask/tut/app/__init__.py:46]
2020-12-30 09:24:10,044 INFO: Microblog startup [in /Users/mazzeogeorge/Code/Flask/tut/app/__init__.py:46]
2020-12-30 09:25:03,111 INFO: Microblog startup [in /Users/mazzeogeorge/Code/Flask/tut/app/__init__.py:46]
2020-12-30 09:26:35,997 INFO: Microblog startup [in /Users/mazzeogeorge/Code/Flask/tut/app/__init__.py:46]
2020-12-30 09:26:54,849 INFO: Microblog startup [in /Users/mazzeogeorge/Code/Flask/tut/app/__init__.py:46]
2020-12-30 09:27:02,299 INFO: Microblog startup [in /Users/mazzeogeorge/Code/Flask/tut/app/__init__.py:46]
2020-12-30 10:08:19,200 INFO: Microblog startup [in /Users/mazzeogeorge/Code/Flask/tut/app/__init__.py:46]
2020-12-30 10:09:38,756 INFO: Microblog startup [in /Users/mazzeogeorge/Code/Flask/tut/app/__init__.py:46]
2020-12-30 10:10:14,312 INFO: Microblog startup [in /Users/mazzeogeorge/Code/Flask/tut/app/__init__.py:46]
2020-12-30 10:12:51,093 INFO: Microblog startup [in /Users/mazzeogeorge/Code/Flask/tut/app/__init__.py:46]
2020-12-30 10:14:50,102 INFO: Microblog startup [in /Users/mazzeogeorge/Code/Flask/tut/app/__init__.py:46]
2020-12-30 10:42:27,691 INFO: Microblog startup [in /Users/mazzeogeorge/Code/Flask/tut/app/__init__.py:46]
2020-12-30 10:44:28,066 INFO: Microblog startup [in /Users/mazzeogeorge/Code/Flask/tut/app/__init__.py:46]
2020-12-30 10:46:33,152 INFO: Microblog startup [in /Users/mazzeogeorge/Code/Flask/tut/app/__init__.py:46]
2020-12-30 10:46:38,449 ERROR: Exception on /user/Bob [GET] [in /Users/mazzeogeorge/Code/Flask/tut/venv/lib/python3.7/site-packages/flask/app.py:1892]
Traceback (most recent call last):
  File "/Users/mazzeogeorge/Code/Flask/tut/venv/lib/python3.7/site-packages/flask/app.py", line 2447, in wsgi_app
    response = self.full_dispatch_request()
  File "/Users/mazzeogeorge/Code/Flask/tut/venv/lib/python3.7/site-packages/flask/app.py", line 1952, in full_dispatch_request
    rv = self.handle_user_exception(e)
  File "/Users/mazzeogeorge/Code/Flask/tut/venv/lib/python3.7/site-packages/flask/app.py", line 1821, in handle_user_exception
    reraise(exc_type, exc_value, tb)
  File "/Users/mazzeogeorge/Code/Flask/tut/venv/lib/python3.7/site-packages/flask/_compat.py", line 39, in reraise
    raise value
  File "/Users/mazzeogeorge/Code/Flask/tut/venv/lib/python3.7/site-packages/flask/app.py", line 1950, in full_dispatch_request
    rv = self.dispatch_request()
  File "/Users/mazzeogeorge/Code/Flask/tut/venv/lib/python3.7/site-packages/flask/app.py", line 1936, in dispatch_request
    return self.view_functions[rule.endpoint](**req.view_args)
  File "/Users/mazzeogeorge/Code/Flask/tut/venv/lib/python3.7/site-packages/flask_login/utils.py", line 272, in decorated_view
    return func(*args, **kwargs)
  File "/Users/mazzeogeorge/Code/Flask/tut/app/routes.py", line 85, in user
    return render_template('user.html', user=user, posts=posts, form=form)
NameError: name 'posts' is not defined
2020-12-30 10:48:24,400 INFO: Microblog startup [in /Users/mazzeogeorge/Code/Flask/tut/app/__init__.py:46]
