2021-01-02 15:10:59,418 ERROR: Exception on /index [POST] [in /Users/mazzeogeorge/Code/Flask/tut/venv/lib/python3.7/site-packages/flask/app.py:1892]
Traceback (most recent call last):
  File "/Users/mazzeogeorge/Code/Flask/tut/venv/lib/python3.7/site-packages/urllib3/connection.py", line 170, in _new_conn
    (self._dns_host, self.port), self.timeout, **extra_kw
  File "/Users/mazzeogeorge/Code/Flask/tut/venv/lib/python3.7/site-packages/urllib3/util/connection.py", line 96, in create_connection
    raise err
  File "/Users/mazzeogeorge/Code/Flask/tut/venv/lib/python3.7/site-packages/urllib3/util/connection.py", line 86, in create_connection
    sock.connect(sa)
ConnectionRefusedError: [Errno 61] Connection refused

During handling of the above exception, another exception occurred:

Traceback (most recent call last):
  File "/Users/mazzeogeorge/Code/Flask/tut/venv/lib/python3.7/site-packages/elasticsearch/connection/http_urllib3.py", line 246, in perform_request
    method, url, body, retries=Retry(False), headers=request_headers, **kw
  File "/Users/mazzeogeorge/Code/Flask/tut/venv/lib/python3.7/site-packages/urllib3/connectionpool.py", line 756, in urlopen
    method, url, error=e, _pool=self, _stacktrace=sys.exc_info()[2]
  File "/Users/mazzeogeorge/Code/Flask/tut/venv/lib/python3.7/site-packages/urllib3/util/retry.py", line 506, in increment
    raise six.reraise(type(error), error, _stacktrace)
  File "/Users/mazzeogeorge/Code/Flask/tut/venv/lib/python3.7/site-packages/urllib3/packages/six.py", line 735, in reraise
    raise value
  File "/Users/mazzeogeorge/Code/Flask/tut/venv/lib/python3.7/site-packages/urllib3/connectionpool.py", line 706, in urlopen
    chunked=chunked,
  File "/Users/mazzeogeorge/Code/Flask/tut/venv/lib/python3.7/site-packages/urllib3/connectionpool.py", line 394, in _make_request
    conn.request(method, url, **httplib_request_kw)
  File "/Users/mazzeogeorge/Code/Flask/tut/venv/lib/python3.7/site-packages/urllib3/connection.py", line 234, in request
    super(HTTPConnection, self).request(method, url, body=body, headers=headers)
  File "/opt/anaconda3/lib/python3.7/http/client.py", line 1244, in request
    self._send_request(method, url, body, headers, encode_chunked)
  File "/opt/anaconda3/lib/python3.7/http/client.py", line 1290, in _send_request
    self.endheaders(body, encode_chunked=encode_chunked)
  File "/opt/anaconda3/lib/python3.7/http/client.py", line 1239, in endheaders
    self._send_output(message_body, encode_chunked=encode_chunked)
  File "/opt/anaconda3/lib/python3.7/http/client.py", line 1026, in _send_output
    self.send(msg)
  File "/opt/anaconda3/lib/python3.7/http/client.py", line 966, in send
    self.connect()
  File "/Users/mazzeogeorge/Code/Flask/tut/venv/lib/python3.7/site-packages/urllib3/connection.py", line 200, in connect
    conn = self._new_conn()
  File "/Users/mazzeogeorge/Code/Flask/tut/venv/lib/python3.7/site-packages/urllib3/connection.py", line 182, in _new_conn
    self, "Failed to establish a new connection: %s" % e
urllib3.exceptions.NewConnectionError: <urllib3.connection.HTTPConnection object at 0x7f8a7510f4d0>: Failed to establish a new connection: [Errno 61] Connection refused

During handling of the above exception, another exception occurred:

Traceback (most recent call last):
  File "/Users/mazzeogeorge/Code/Flask/tut/venv/lib/python3.7/site-packages/flask/app.py", line 2447, in wsgi_app
    response = self.full_dispatch_request()
  File "/Users/mazzeogeorge/Code/Flask/tut/venv/lib/python3.7/site-packages/flask/app.py", line 1952, in full_dispatch_request
    rv = self.handle_user_exception(e)
  File "/Users/mazzeogeorge/Code/Flask/tut/venv/lib/python3.7/site-packages/flask/app.py", line 1821, in handle_user_exception
    reraise(exc_type, exc_value, tb)
  File "/Users/mazzeogeorge/Code/Flask/tut/venv/lib/python3.7/site-packages/flask/_compat.py", line 39, in reraise
    raise value
  File "/Users/mazzeogeorge/Code/Flask/tut/venv/lib/python3.7/site-packages/flask/app.py", line 1950, in full_dispatch_request
    rv = self.dispatch_request()
  File "/Users/mazzeogeorge/Code/Flask/tut/venv/lib/python3.7/site-packages/flask/app.py", line 1936, in dispatch_request
    return self.view_functions[rule.endpoint](**req.view_args)
  File "/Users/mazzeogeorge/Code/Flask/tut/venv/lib/python3.7/site-packages/flask_login/utils.py", line 272, in decorated_view
    return func(*args, **kwargs)
  File "/Users/mazzeogeorge/Code/Flask/tut/app/main/routes.py", line 52, in index
    db.session.commit()
  File "/Users/mazzeogeorge/Code/Flask/tut/venv/lib/python3.7/site-packages/sqlalchemy/orm/scoping.py", line 163, in do
    return getattr(self.registry(), name)(*args, **kwargs)
  File "/Users/mazzeogeorge/Code/Flask/tut/venv/lib/python3.7/site-packages/sqlalchemy/orm/session.py", line 1046, in commit
    self.transaction.commit()
  File "/Users/mazzeogeorge/Code/Flask/tut/venv/lib/python3.7/site-packages/sqlalchemy/orm/session.py", line 511, in commit
    self.session.dispatch.after_commit(self.session)
  File "/Users/mazzeogeorge/Code/Flask/tut/venv/lib/python3.7/site-packages/sqlalchemy/event/attr.py", line 320, in __call__
    fn(*args, **kw)
  File "/Users/mazzeogeorge/Code/Flask/tut/app/models.py", line 122, in after_commit
    add_to_index(obj.__tablename__, obj)
  File "/Users/mazzeogeorge/Code/Flask/tut/app/search.py", line 11, in add_to_index
    current_app.elasticsearch.index(index=index, id=model.id, body=payload)
  File "/Users/mazzeogeorge/Code/Flask/tut/venv/lib/python3.7/site-packages/elasticsearch/client/utils.py", line 152, in _wrapped
    return func(*args, params=params, headers=headers, **kwargs)
  File "/Users/mazzeogeorge/Code/Flask/tut/venv/lib/python3.7/site-packages/elasticsearch/client/__init__.py", line 403, in index
    body=body,
  File "/Users/mazzeogeorge/Code/Flask/tut/venv/lib/python3.7/site-packages/elasticsearch/transport.py", line 390, in perform_request
    raise e
  File "/Users/mazzeogeorge/Code/Flask/tut/venv/lib/python3.7/site-packages/elasticsearch/transport.py", line 365, in perform_request
    timeout=timeout,
  File "/Users/mazzeogeorge/Code/Flask/tut/venv/lib/python3.7/site-packages/elasticsearch/connection/http_urllib3.py", line 258, in perform_request
    raise ConnectionError("N/A", str(e), e)
elasticsearch.exceptions.ConnectionError: ConnectionError(<urllib3.connection.HTTPConnection object at 0x7f8a7510f4d0>: Failed to establish a new connection: [Errno 61] Connection refused) caused by: NewConnectionError(<urllib3.connection.HTTPConnection object at 0x7f8a7510f4d0>: Failed to establish a new connection: [Errno 61] Connection refused)
2021-01-02 16:18:13,919 INFO: Microblog startup [in /Users/mazzeogeorge/Code/Flask/tut/app/__init__.py:83]
2021-01-02 16:18:13,936 INFO: Microblog startup [in /Users/mazzeogeorge/Code/Flask/tut/app/__init__.py:100]
2021-01-02 16:18:13,936 INFO: Microblog startup [in /Users/mazzeogeorge/Code/Flask/tut/app/__init__.py:100]
2021-01-02 17:23:55,805 INFO: Microblog startup [in /Users/mazzeogeorge/Code/Flask/tut/app/__init__.py:83]
2021-01-02 17:23:55,805 INFO: Microblog startup [in /Users/mazzeogeorge/Code/Flask/tut/app/__init__.py:100]
2021-01-02 17:23:55,805 INFO: Microblog startup [in /Users/mazzeogeorge/Code/Flask/tut/app/__init__.py:100]
2021-01-02 17:46:52,550 INFO: Microblog startup [in /Users/mazzeogeorge/Code/Flask/tut/app/__init__.py:83]
2021-01-02 17:46:52,551 INFO: Microblog startup [in /Users/mazzeogeorge/Code/Flask/tut/app/__init__.py:100]
2021-01-02 17:46:52,551 INFO: Microblog startup [in /Users/mazzeogeorge/Code/Flask/tut/app/__init__.py:100]
2021-01-02 17:52:43,395 INFO: Microblog startup [in /Users/mazzeogeorge/Code/Flask/tut/app/__init__.py:83]
2021-01-02 17:52:43,396 INFO: Microblog startup [in /Users/mazzeogeorge/Code/Flask/tut/app/__init__.py:100]
2021-01-02 17:52:43,396 INFO: Microblog startup [in /Users/mazzeogeorge/Code/Flask/tut/app/__init__.py:100]
